import asyncio
import os
from typing import Any

import pytest
from bluesky.run_engine import RunEngine

# Prevent pytest from catching exceptions when debugging in vscode so that break on
# exception works correctly (see: https://github.com/pytest-dev/pytest/issues/7409)
if os.getenv("PYTEST_RAISE", "0") == "1":

    @pytest.hookimpl(tryfirst=True)
    def pytest_exception_interact(call: pytest.CallInfo[Any]):
        if call.excinfo is not None:
            raise call.excinfo.value
        else:
            raise RuntimeError(
                f"{call} has no exception data, an unknown error has occurred"
            )

    @pytest.hookimpl(tryfirst=True)
    def pytest_internalerror(excinfo: pytest.ExceptionInfo[Any]):
        raise excinfo.value


@pytest.fixture(scope="function")
def RE(request):
    loop = asyncio.new_event_loop()
    loop.set_debug(True)
    RE = RunEngine({}, call_returns_result=True, loop=loop)

    def clean_event_loop():
        if RE.state not in ("idle", "panicked"):
            # try:
            RE.halt()
        # except TransitionError:
        #     pass
        loop.call_soon_threadsafe(loop.stop)
        RE._th.join()  # noqa: SLF001
        loop.close()

    request.addfinalizer(clean_event_loop)
    return RE
